09/02/25 (16:22:21) | ERROR: <urlopen error _ssl.c:1001: The handshake operation timed out>
Traceback (most recent call last):
  File "/opt/homebrew/Cellar/python@3.13/3.13.1/Frameworks/Python.framework/Versions/3.13/lib/python3.13/urllib/request.py", line 1319, in do_open
    h.request(req.get_method(), req.selector, req.data, headers,
    ~~~~~~~~~^^^^^^^^^^^^^^^^^^^^^^^^^^^^^^^^^^^^^^^^^^^^^^^^^^^
              encode_chunked=req.has_header('Transfer-encoding'))
              ^^^^^^^^^^^^^^^^^^^^^^^^^^^^^^^^^^^^^^^^^^^^^^^^^^^
  File "/opt/homebrew/Cellar/python@3.13/3.13.1/Frameworks/Python.framework/Versions/3.13/lib/python3.13/http/client.py", line 1336, in request
    self._send_request(method, url, body, headers, encode_chunked)
    ~~~~~~~~~~~~~~~~~~^^^^^^^^^^^^^^^^^^^^^^^^^^^^^^^^^^^^^^^^^^^^
  File "/opt/homebrew/Cellar/python@3.13/3.13.1/Frameworks/Python.framework/Versions/3.13/lib/python3.13/http/client.py", line 1382, in _send_request
    self.endheaders(body, encode_chunked=encode_chunked)
    ~~~~~~~~~~~~~~~^^^^^^^^^^^^^^^^^^^^^^^^^^^^^^^^^^^^^
  File "/opt/homebrew/Cellar/python@3.13/3.13.1/Frameworks/Python.framework/Versions/3.13/lib/python3.13/http/client.py", line 1331, in endheaders
    self._send_output(message_body, encode_chunked=encode_chunked)
    ~~~~~~~~~~~~~~~~~^^^^^^^^^^^^^^^^^^^^^^^^^^^^^^^^^^^^^^^^^^^^^
  File "/opt/homebrew/Cellar/python@3.13/3.13.1/Frameworks/Python.framework/Versions/3.13/lib/python3.13/http/client.py", line 1091, in _send_output
    self.send(msg)
    ~~~~~~~~~^^^^^
  File "/opt/homebrew/Cellar/python@3.13/3.13.1/Frameworks/Python.framework/Versions/3.13/lib/python3.13/http/client.py", line 1035, in send
    self.connect()
    ~~~~~~~~~~~~^^
  File "/opt/homebrew/Cellar/python@3.13/3.13.1/Frameworks/Python.framework/Versions/3.13/lib/python3.13/http/client.py", line 1477, in connect
    self.sock = self._context.wrap_socket(self.sock,
                ~~~~~~~~~~~~~~~~~~~~~~~~~^^^^^^^^^^^
                                          server_hostname=server_hostname)
                                          ^^^^^^^^^^^^^^^^^^^^^^^^^^^^^^^^
  File "/opt/homebrew/Cellar/python@3.13/3.13.1/Frameworks/Python.framework/Versions/3.13/lib/python3.13/ssl.py", line 455, in wrap_socket
    return self.sslsocket_class._create(
           ~~~~~~~~~~~~~~~~~~~~~~~~~~~~^
        sock=sock,
        ^^^^^^^^^^
    ...<5 lines>...
        session=session
        ^^^^^^^^^^^^^^^
    )
    ^
  File "/opt/homebrew/Cellar/python@3.13/3.13.1/Frameworks/Python.framework/Versions/3.13/lib/python3.13/ssl.py", line 1076, in _create
    self.do_handshake()
    ~~~~~~~~~~~~~~~~~^^
  File "/opt/homebrew/Cellar/python@3.13/3.13.1/Frameworks/Python.framework/Versions/3.13/lib/python3.13/ssl.py", line 1372, in do_handshake
    self._sslobj.do_handshake()
    ~~~~~~~~~~~~~~~~~~~~~~~~~^^
TimeoutError: _ssl.c:1001: The handshake operation timed out

During handling of the above exception, another exception occurred:

Traceback (most recent call last):
  File "/opt/homebrew/bin/bpytop", line 5029, in _checker
    with urllib.request.urlopen("https://github.com/aristocratos/bpytop/raw/master/bpytop.py", timeout=5) as source: # type: ignore
         ~~~~~~~~~~~~~~~~~~~~~~^^^^^^^^^^^^^^^^^^^^^^^^^^^^^^^^^^^^^^^^^^^^^^^^^^^^^^^^^^^^^^^^^^^^^^^^^^
  File "/opt/homebrew/Cellar/python@3.13/3.13.1/Frameworks/Python.framework/Versions/3.13/lib/python3.13/urllib/request.py", line 189, in urlopen
    return opener.open(url, data, timeout)
           ~~~~~~~~~~~^^^^^^^^^^^^^^^^^^^^
  File "/opt/homebrew/Cellar/python@3.13/3.13.1/Frameworks/Python.framework/Versions/3.13/lib/python3.13/urllib/request.py", line 489, in open
    response = self._open(req, data)
  File "/opt/homebrew/Cellar/python@3.13/3.13.1/Frameworks/Python.framework/Versions/3.13/lib/python3.13/urllib/request.py", line 506, in _open
    result = self._call_chain(self.handle_open, protocol, protocol +
                              '_open', req)
  File "/opt/homebrew/Cellar/python@3.13/3.13.1/Frameworks/Python.framework/Versions/3.13/lib/python3.13/urllib/request.py", line 466, in _call_chain
    result = func(*args)
  File "/opt/homebrew/Cellar/python@3.13/3.13.1/Frameworks/Python.framework/Versions/3.13/lib/python3.13/urllib/request.py", line 1367, in https_open
    return self.do_open(http.client.HTTPSConnection, req,
           ~~~~~~~~~~~~^^^^^^^^^^^^^^^^^^^^^^^^^^^^^^^^^^
                        context=self._context)
                        ^^^^^^^^^^^^^^^^^^^^^^
  File "/opt/homebrew/Cellar/python@3.13/3.13.1/Frameworks/Python.framework/Versions/3.13/lib/python3.13/urllib/request.py", line 1322, in do_open
    raise URLError(err)
urllib.error.URLError: <urlopen error _ssl.c:1001: The handshake operation timed out>
10/02/25 (13:46:18) | ERROR: <urlopen error [Errno 8] nodename nor servname provided, or not known>
Traceback (most recent call last):
  File "/opt/homebrew/Cellar/python@3.13/3.13.1/Frameworks/Python.framework/Versions/3.13/lib/python3.13/urllib/request.py", line 1319, in do_open
    h.request(req.get_method(), req.selector, req.data, headers,
    ~~~~~~~~~^^^^^^^^^^^^^^^^^^^^^^^^^^^^^^^^^^^^^^^^^^^^^^^^^^^
              encode_chunked=req.has_header('Transfer-encoding'))
              ^^^^^^^^^^^^^^^^^^^^^^^^^^^^^^^^^^^^^^^^^^^^^^^^^^^
  File "/opt/homebrew/Cellar/python@3.13/3.13.1/Frameworks/Python.framework/Versions/3.13/lib/python3.13/http/client.py", line 1336, in request
    self._send_request(method, url, body, headers, encode_chunked)
    ~~~~~~~~~~~~~~~~~~^^^^^^^^^^^^^^^^^^^^^^^^^^^^^^^^^^^^^^^^^^^^
  File "/opt/homebrew/Cellar/python@3.13/3.13.1/Frameworks/Python.framework/Versions/3.13/lib/python3.13/http/client.py", line 1382, in _send_request
    self.endheaders(body, encode_chunked=encode_chunked)
    ~~~~~~~~~~~~~~~^^^^^^^^^^^^^^^^^^^^^^^^^^^^^^^^^^^^^
  File "/opt/homebrew/Cellar/python@3.13/3.13.1/Frameworks/Python.framework/Versions/3.13/lib/python3.13/http/client.py", line 1331, in endheaders
    self._send_output(message_body, encode_chunked=encode_chunked)
    ~~~~~~~~~~~~~~~~~^^^^^^^^^^^^^^^^^^^^^^^^^^^^^^^^^^^^^^^^^^^^^
  File "/opt/homebrew/Cellar/python@3.13/3.13.1/Frameworks/Python.framework/Versions/3.13/lib/python3.13/http/client.py", line 1091, in _send_output
    self.send(msg)
    ~~~~~~~~~^^^^^
  File "/opt/homebrew/Cellar/python@3.13/3.13.1/Frameworks/Python.framework/Versions/3.13/lib/python3.13/http/client.py", line 1035, in send
    self.connect()
    ~~~~~~~~~~~~^^
  File "/opt/homebrew/Cellar/python@3.13/3.13.1/Frameworks/Python.framework/Versions/3.13/lib/python3.13/http/client.py", line 1470, in connect
    super().connect()
    ~~~~~~~~~~~~~~~^^
  File "/opt/homebrew/Cellar/python@3.13/3.13.1/Frameworks/Python.framework/Versions/3.13/lib/python3.13/http/client.py", line 1001, in connect
    self.sock = self._create_connection(
                ~~~~~~~~~~~~~~~~~~~~~~~^
        (self.host,self.port), self.timeout, self.source_address)
        ^^^^^^^^^^^^^^^^^^^^^^^^^^^^^^^^^^^^^^^^^^^^^^^^^^^^^^^^^
  File "/opt/homebrew/Cellar/python@3.13/3.13.1/Frameworks/Python.framework/Versions/3.13/lib/python3.13/socket.py", line 840, in create_connection
    for res in getaddrinfo(host, port, 0, SOCK_STREAM):
               ~~~~~~~~~~~^^^^^^^^^^^^^^^^^^^^^^^^^^^^
  File "/opt/homebrew/Cellar/python@3.13/3.13.1/Frameworks/Python.framework/Versions/3.13/lib/python3.13/socket.py", line 975, in getaddrinfo
    for res in _socket.getaddrinfo(host, port, family, type, proto, flags):
               ~~~~~~~~~~~~~~~~~~~^^^^^^^^^^^^^^^^^^^^^^^^^^^^^^^^^^^^^^^^
socket.gaierror: [Errno 8] nodename nor servname provided, or not known

During handling of the above exception, another exception occurred:

Traceback (most recent call last):
  File "/opt/homebrew/bin/bpytop", line 5029, in _checker
    with urllib.request.urlopen("https://github.com/aristocratos/bpytop/raw/master/bpytop.py", timeout=5) as source: # type: ignore
         ~~~~~~~~~~~~~~~~~~~~~~^^^^^^^^^^^^^^^^^^^^^^^^^^^^^^^^^^^^^^^^^^^^^^^^^^^^^^^^^^^^^^^^^^^^^^^^^^
  File "/opt/homebrew/Cellar/python@3.13/3.13.1/Frameworks/Python.framework/Versions/3.13/lib/python3.13/urllib/request.py", line 189, in urlopen
    return opener.open(url, data, timeout)
           ~~~~~~~~~~~^^^^^^^^^^^^^^^^^^^^
  File "/opt/homebrew/Cellar/python@3.13/3.13.1/Frameworks/Python.framework/Versions/3.13/lib/python3.13/urllib/request.py", line 489, in open
    response = self._open(req, data)
  File "/opt/homebrew/Cellar/python@3.13/3.13.1/Frameworks/Python.framework/Versions/3.13/lib/python3.13/urllib/request.py", line 506, in _open
    result = self._call_chain(self.handle_open, protocol, protocol +
                              '_open', req)
  File "/opt/homebrew/Cellar/python@3.13/3.13.1/Frameworks/Python.framework/Versions/3.13/lib/python3.13/urllib/request.py", line 466, in _call_chain
    result = func(*args)
  File "/opt/homebrew/Cellar/python@3.13/3.13.1/Frameworks/Python.framework/Versions/3.13/lib/python3.13/urllib/request.py", line 1367, in https_open
    return self.do_open(http.client.HTTPSConnection, req,
           ~~~~~~~~~~~~^^^^^^^^^^^^^^^^^^^^^^^^^^^^^^^^^^
                        context=self._context)
                        ^^^^^^^^^^^^^^^^^^^^^^
  File "/opt/homebrew/Cellar/python@3.13/3.13.1/Frameworks/Python.framework/Versions/3.13/lib/python3.13/urllib/request.py", line 1322, in do_open
    raise URLError(err)
urllib.error.URLError: <urlopen error [Errno 8] nodename nor servname provided, or not known>
26/04/25 (00:55:13) | ERROR: Data collection thread failed with exception: [Errno 12] Cannot allocate memory
Traceback (most recent call last):
  File "/opt/homebrew/bin/bpytop", line 2958, in _runner
    collector._collect()
    ~~~~~~~~~~~~~~~~~~^^
  File "/opt/homebrew/bin/bpytop", line 3567, in _collect
    up_stat = psutil.net_if_stats()
  File "/opt/homebrew/Cellar/bpytop/1.0.68/libexec/lib/python3.13/site-packages/psutil/__init__.py", line 2276, in net_if_stats
    return _psplatform.net_if_stats()
           ~~~~~~~~~~~~~~~~~~~~~~~~^^
  File "/opt/homebrew/Cellar/bpytop/1.0.68/libexec/lib/python3.13/site-packages/psutil/_psosx.py", line 265, in net_if_stats
    names = net_io_counters().keys()
            ~~~~~~~~~~~~~~~^^
OSError: [Errno 12] Cannot allocate memory
26/04/25 (00:55:15) | WARNING: Exiting with errorcode (1). Runtime 0:42:00 

